Workbook

Sheet A7.0.DM Biểu mẫu
B2: Dự án: | C2: XÂY DỰNG HỆ THỐNG ĐÁNH GIÁ HIỆU QUẢ CÔNG VIỆC
B3: Yêu cầu: | C3: CÔNG TY CỔ PHẦN CẤP NƯỚC ĐÀ NẴNG
B4: Tư vấn: | C4: BrainMark Vietnam
B5: BIỂU MẪU_A7.BRAINKPI
B6: XÂY DỰNG HỆ THỐNG ĐÁNH GIÁ HIỆU QUẢ CÔNG VIỆC
B8: STT | C8: MÃ SỐ BIỂU MẪU | D8: TÊN BIỂU MẪU
B9: 1 | C9: A7.1 | D9: Mục tiêu Công ty
B10: 2 | C10: A7.2 | D10: Mục tiêu Tổng hợp toàn Công ty
B11: 3 | C11: A7.3 | D11: Mục tiêu Phòng (Năm)
B12: 4 | C12: A7.4 | D12: Mục tiêu Phòng (Quý)
B13: 5 | C13: A7.5 | D13: Mục tiêu Phòng (Tháng)
B14: 6 | C14: A7.6 | D14: Mục tiêu Nhân viên (Năm)
B15: 7 | C15: A7.7 | D15: Mục tiêu Nhân viên (Quý)
B16: 8 | C16: A7.8 | D16: KPI Công ty Năm
B17: 9 | C17: A7.9 | D17: KPI Phòng Năm
B18: 10 | C18: A7.10 | D18: Ngân hàng KPI cá nhân
B19: 11 | C19: A7.11 | D19: KPI Cá nhân Năm
B20: 12 | C20: A7.12 | D20: KPI Quản lý (Trưởng phòng) Năm
... B26: 18 | C26: A7.18 | D26: Tổng hợp KPI Phòng Năm

Sheet A7.1.Muc tieu Công ty
B2: Dự án: | C2: XÂY DỰNG HỆ THỐNG ĐÁNH GIÁ HIỆU QUẢ CÔNG VIỆC
B3: Yêu cầu: | C3: CÔNG TY CỔ PHẦN CẤP NƯỚC ĐÀ NẴNG
B4: Tư vấn: | C4: BrainMark Vietnam
B6: A7.1 | C6: MỤC TIÊU CÔNG TY - NĂM 2025
B9: Stt | C9: MỤC TIÊU CÔNG TY | D9: TRỌNG SỐ (%)
C10: VẬN HÀNH (B) | D10: 0.4
B11: 1 | C11: Sản lượng nước sản xuất đạt 122.030.057 m³, tăng 3% so với thực hiện năm trước | D11: 0.15
B12: 2 | C12: Sản lượng nước tiêu thụ đạt 106.776.300 m³, tăng 3% so với năm trước | D12: 0.3
B13: 3 | C13: Tỷ lệ thất thoát nước không vượt quá 11,33% | D13: 0.3
B14: 4 | C14: Số lượng thay thế đồng hồ đạt 23.824 chiếc/năm | D14: 0.15
B15: 5 | C15: Tỷ lệ khu vực được kiểm soát áp lực nước/tổng khu vực cấp nước đạt 100% | D15: 0.1
C16: TÀI CHÍNH (F) | D16: 0.35
B17: 1 | C17: Doanh thu ngành nước đạt 733,530 tỷ, tăng 15% so với năm trước | D17: 0.15
B18: 2 | C18: Doanh thu ngành xây lắp đạt 3 tỷ | D18: 0.1
B19: 3 | C19: Chỉ tiêu đơn giá nước bình quân đạt 7.020 đồng/m³ | D19: 0.3
B20: 4 | C20: Lợi nhuận trước thuế đạt 161,667 tỷ, tăng 44% so với năm trước | D20: 0.15
B21: 5 | C21: Tỷ lệ công nợ ngành nước/Doanh thu ngành nước không quá 1,4% | D21: 0.1
B22: 6 | C22: Chi phí vận hành (gồm chi phí hoá chất, điện năng)/m³ nước không vượt quá 574 đồng/m³ | D22: 0.2
C23: KHÁCH HÀNG (C) | D23: 0.1
B24: 1 | C24: Số lượng đồng hồ khách hàng đặt mới đạt 7.420 chiếc | D24: 0.2
B25: 2 | C25: Đảm bảo mức độ hài lòng khách hàng được khảo sát đạt ≥ 80% | D25: 0.15
B26: 3 | C26: Thời gian xử lý đơn khiếu nại của KH (có báo cáo bằng văn bản) trung bình không quá 05 ngày làm việc kể từ ngày tiếp nhận đơn | D26: 0.15
B27: 4 | C27: Tỷ lệ phản ánh về chất lượng dịch vụ giảm 5% so với tổng phản ánh năm trước | D27: 0.15
B28: 5 | C28: Đảm bảo ≥ 2% khách hàng/tổng số khách hàng được thiết lập hồ sơ quản lý (tính scan hợp đồng để tạo mã dữ liệu KH) | D28: 0.2
B29: 6 | C29: Tỷ lệ người dùng đăng ký Zalo OA của Công ty đạt ≥ 86% | D29: 0.15
C30: PHÁT TRIỂN ĐỔI MỚI | D30: 0.15
B31: 1 | C31: Hoàn thành xây dựng và vận hành hệ thống BSC-KPI trước ngày 31/12/2025 | D31: 0.4
B32: 2 | C32: Đảm bảo có ít nhất 01 sáng kiến cải tiến cấp Công ty | D32: 0.2
B33: 3 | C33: Tổ chức 03 khóa đào tạo | D33: 0.2
B34: 4 | C34: Có ít nhất 01 đề tài/dự án phát triển KHCN được ứng dụng | D34: 0.2
C35: TOTAL | D35: =D30+D23+D16+D10 -> 1
B37: Người lập (Prepared by) Phê duyệt (Approved by)
B44: Ngày (Date) ....../....../...... Ngày (Date) ....../....../.....

Sheet A7.2.Mục tiêu tổng hợp
F1: nguyên tắc: không có mục tiêu nào còn lại ở cấp công ty.
B2: Dự án: | C2: XÂY DỰNG HỆ THỐNG ĐÁNH GIÁ HIỆU QUẢ CÔNG VIỆC | F2: (*) Anh Chị vui lòng rà soát lại các mục tiêu được Công ty giao và bổ sung các chỉ tiêu X và trọng số của từng mục tiêu tại sheet A7.3. Mỗi phương diện Vận hành - Tài chính- Khách hàng - Phát triển có từ 3 - 5 mục tiêu, các đơn vị chưa được phân bổ đủ 3 - 5 mục tiêu vui lòng đặt thêm mục tiêu dựa trên chức năng nhiệm vụ quan trọng của đơn vị (tham khảo thêm file mục tiêu tham khảo BrainMark gửi) để đủ số lượng mục tiêu và vui lòng tô màu các ô mục tiêu Phòng Ban bổ sung để tiện rà soát.
B3: Yêu cầu: | C3: CÔNG TY CỔ PHẦN CẤP NƯỚC ĐÀ NẴNG
B4: Tư vấn: | C4: BrainMark Vietnam
B6: A7.2 | C6: MỤC TIÊU TOÀN CÔNG TY - NĂM 2025
B9: Stt | C9: MỤC TIÊU CÔNG TY | D9: TRỌNG SỐ (%) | E9: XÍ NGHIỆP CẤP NƯỚC KV I (Hải Châu - Thanh Khê) | F9: TRỌNG SỐ (%) | G9: XÍ NGHIỆP CẤP NƯỚC KV II (Cẩm Lệ) | H9: TRỌNG SỐ (%) | I9: XÍ NGHIỆP CẤP NƯỚC KV III (Sơn Trà - Ngũ Hành Sơn) | J9: TRỌNG SỐ (%) | K9: XÍ NGHIỆP CẤP NƯỚC KV IV (Liên Chiểu) | L9: TRỌNG SỐ (%) | M9: XÍ NGHIỆP XÂY LẮP | N9: TRỌNG SỐ (%) | O9: TT QUẢN LÝ VẬN HÀNH | P9: TRỌNG SỐ (%) | Q9: BAN KẾ HOẠCH | R9: TRỌNG SỐ (%) | S9: BAN KỸ THUẬT | T9: TRỌNG SỐ (%) | U9: BAN HCNS | V9: TRỌNG SỐ (%) | W9: BAN TCKT | X9: TRỌNG SỐ (%) | Y9: TRUNG TÂM CNTT | Z9: TRỌNG SỐ (%)
C10: VẬN HÀNH (B) | D10: 0.4 | F10: 0.4
B11: 1 | C11: Sản lượng nước sản xuất đạt 122.030.057 m³, tăng 3% so với thực hiện năm trước | D11: 0.15 | E11: Chiều dài đường ống cải tạo di dời (quý 4) đạt X km | F11: 0.15 | G11: Sản lượng nước sản xuất đạt X m³, tăng 3% so với thực hiện năm trước | I11: Sản lượng nước sản xuất đạt X m³, tăng 3% so với thực hiện năm trước | K11: Sản lượng nước sản xuất đạt X m³, tăng 3% so với thực hiện năm trước | M11: x | O11: Sản lượng nước sản xuất đạt X m³, tăng 3% so với thực hiện năm trước | Q11: Sản lượng nước sản xuất đạt 122.030.057 m³, tăng 3% so với thực hiện năm trước | S11: x | U11: x | W11: x | Y11: x
B12: 2 | C12: Sản lượng nước tiêu thụ đạt 106.776.300 m³, tăng 3% so với năm trước | D12: 0.3 | E12: Sản lượng nước tiêu thụ đạt X m³, tăng 3% so với năm trước | F12: 0.35 | G12: Sản lượng nước tiêu thụ đạt X m³, tăng 3% so với năm trước | I12: Sản lượng nước tiêu thụ đạt X m³, tăng 3% so với năm trước | K12: Sản lượng nước tiêu thụ đạt X m³, tăng 3% so với năm trước | Q12: Sản lượng nước tiêu thụ đạt 106.776.300 m³, tăng 3% so với năm trước
B13: 3 | C13: Tỷ lệ thất thoát nước không vượt quá 11,33% | D13: 0.3 | E13: Tỷ lệ thất thoát nước không vượt quá X % | F13: 0.25 | G13: Tỷ lệ thất thoát nước không vượt quá X % | I13: Tỷ lệ thất thoát nước không vượt quá X % | K13: Tỷ lệ thất thoát nước không vượt quá X % | M13: Tỷ lệ thất thoát nước không vượt quá 11,33% | O13: Tỷ lệ thất thoát nước không vượt quá X % | Q13: Tỷ lệ thất thoát nước không vượt quá 11,33% | S13: Tỷ lệ thất thoát nước không vượt quá 11,33%
B14: 4 | C14: Số lượng thay thế đồng hồ đạt 23.824 chiếc/năm | D14: 0.15 | E14: Số lượng thay thế đồng hồ đạt X chiếc/năm | F14: 0.15 | G14: Số lượng thay thế đồng hồ đạt X chiếc/năm | I14: Số lượng thay thế đồng hồ đạt X chiếc/năm | K14: Số lượng thay thế đồng hồ đạt X chiếc/năm | Q14: Số lượng thay thế đồng hồ đạt 23.824 chiếc/năm | W14: x
B15: 5 | C15: Tỷ lệ khu vực được kiểm soát áp lực nước/tổng khu vực cấp nước đạt 100% | D15: 0.1 | E15: Tỷ lệ khu vực được kiểm soát áp lực nước/tổng khu vực cấp nước đạt 100% | F15: 0.1 | G15: Tỷ lệ khu vực được kiểm soát áp lực nước/tổng khu vực cấp nước đạt 100% | I15: Tỷ lệ khu vực được kiểm soát áp lực nước/tổng khu vực cấp nước đạt 100% | K15: Tỷ lệ khu vực được kiểm soát áp lực nước/tổng khu vực cấp nước đạt 100% | O15: Tỷ lệ khu vực được kiểm soát áp lực nước/tổng khu vực cấp nước đạt 100% | S15: Tỷ lệ khu vực được kiểm soát áp lực nước/tổng khu vực cấp nước đạt 100%
C16: TÀI CHÍNH (F) | D16: 0.35
B17: 1 | C17: Doanh thu ngành nước đạt 733,530 tỷ, tăng 15% so với năm trước | D17: 0.15 | E17: Doanh thu ngành nước đạt X tỷ, tăng 15% so với năm trước | G17: Doanh thu ngành nước đạt X tỷ, tăng 15% so với năm trước | I17: Doanh thu ngành nước đạt X tỷ, tăng 15% so với năm trước | K17: Doanh thu ngành nước đạt X tỷ, tăng 15% so với năm trước | W17: Doanh thu ngành nước đạt 733,530 tỷ, tăng 15% so với năm trước
B18: 2 | C18: Doanh thu ngành xây lắp đạt 3 tỷ | D18: 0.1 | E18: Doanh thu ngành xây lắp đạt X tỷ | G18: Doanh thu ngành xây lắp đạt X tỷ | I18: Doanh thu ngành xây lắp đạt X tỷ | K18: Doanh thu ngành xây lắp đạt X tỷ | M18: Doanh thu ngành xây lắp đạt X tỷ | W18: Doanh thu ngành xây lắp đạt 3 tỷ
B19: 3 | C19: Chỉ tiêu đơn giá nước bình quân đạt 7.020 đồng/m³ | D19: 0.3 | E19: Chỉ tiêu đơn giá nước bình quân đạt X đồng/m³ | G19: Chỉ tiêu đơn giá nước bình quân đạt X đồng/m³ | I19: Chỉ tiêu đơn giá nước bình quân đạt X đồng/m³ | K19: Chỉ tiêu đơn giá nước bình quân đạt X đồng/m³ | W19: Chỉ tiêu đơn giá nước bình quân đạt 7.020 đồng/m³
B20: 4 | C20: Lợi nhuận trước thuế đạt 161,667 tỷ, tăng 44% so với năm trước | D20: 0.15 | W20: Lợi nhuận trước thuế đạt 161,667 tỷ, tăng 44% so với năm trước
B21: 5 | C21: Tỷ lệ công nợ ngành nước/Doanh thu ngành nước không quá 1,4% | D21: 0.1 | E21: Tỷ lệ công nợ ngành nước/Doanh thu ngành nước không quá X% | G21: Tỷ lệ công nợ ngành nước/Doanh thu ngành nước không quá X% | I21: Tỷ lệ công nợ ngành nước/Doanh thu ngành nước không quá X% | K21: Tỷ lệ công nợ ngành nước/Doanh thu ngành nước không quá X% | W21: Tỷ lệ công nợ ngành nước/Doanh thu ngành nước không quá 1,4%
B22: 6 | C22: Chi phí vận hành (gồm chi phí hoá chất, điện năng)/m³ nước không vượt quá 574 đồng/m³ | D22: 0.2 | G22: Chi phí vận hành (gồm chi phí hoá chất, điện năng)/m³ nước không vượt quá X đồng/m³ | I22: Chi phí vận hành (gồm chi phí hoá chất, điện năng)/m³ nước không vượt quá X đồng/m³ | K22: Chi phí vận hành (gồm chi phí hoá chất, điện năng)/m³ nước không vượt quá X đồng/m³ | O22: Chi phí vận hành (gồm chi phí hoá chất, điện năng)/m³ nước không vượt quá X đồng/m³ | W22: Chi phí vận hành (gồm chi phí hoá chất, điện năng)/m³ nước không vượt quá 574 đồng/m³
C23: KHÁCH HÀNG (C) | D23: 0.1
B24: 1 | C24: Số lượng đồng hồ khách hàng đặt mới đạt 7.420 chiếc | D24: 0.2 | E24: Số lượng đồng hồ khách hàng đặt mới đạt X chiếc | G24: Số lượng đồng hồ khách hàng đặt mới đạt X chiếc | I24: Số lượng đồng hồ khách hàng đặt mới đạt X chiếc | K24: Số lượng đồng hồ khách hàng đặt mới đạt X chiếc
B25: 2 | C25: Đảm bảo mức độ hài lòng khách hàng được khảo sát đạt ≥ 80% | D25: 0.15 | E25: Đảm bảo mức độ hài lòng khách hàng được khảo sát đạt ≥ 80% | G25: Đảm bảo mức độ hài lòng khách hàng được khảo sát đạt ≥ 80% | I25: Đảm bảo mức độ hài lòng khách hàng được khảo sát đạt ≥ 80% | K25: Đảm bảo mức độ hài lòng khách hàng được khảo sát đạt ≥ 80% | U25: Đảm bảo mức độ hài lòng khách hàng được khảo sát đạt ≥ 80%
B26: 3 | C26: Thời gian xử lý đơn khiếu nại của KH (có báo cáo bằng văn bản) trung bình không quá 05 ngày làm việc kể từ ngày tiếp nhận đơn | D26: 0.15 | E26: Thời gian xử lý đơn khiếu nại của KH (có báo cáo bằng văn bản) do XN tự xử lý trung bình không quá 03 ngày làm việc kể từ ngày tiếp nhận đơn | G26: Thời gian xử lý đơn khiếu nại của KH (có báo cáo bằng văn bản) do XN tự xử lý trung bình không quá 03 ngày làm việc kể từ ngày tiếp nhận đơn | I26: Thời gian xử lý đơn khiếu nại của KH (có báo cáo bằng văn bản) do XN tự xử lý trung bình không quá 03 ngày làm việc kể từ ngày tiếp nhận đơn | K26: Thời gian xử lý đơn khiếu nại của KH (có báo cáo bằng văn bản) do XN tự xử lý trung bình không quá 03 ngày làm việc kể từ ngày tiếp nhận đơn | O26: Thời gian xử lý đơn khiếu nại của KH (có báo cáo bằng văn bản) trung bình không quá 05 ngày làm việc kể từ ngày tiếp nhận đơn | Q26: Thời gian xử lý đơn khiếu nại của KH (có báo cáo bằng văn bản) trung bình không quá 05 ngày làm việc kể từ ngày tiếp nhận đơn | S26: Thời gian xử lý đơn khiếu nại của KH (có báo cáo bằng văn bản) trung bình không quá 05 ngày làm việc kể từ ngày tiếp nhận đơn | U26: Thời gian xử lý đơn khiếu nại của KH (có báo cáo bằng văn bản) trung bình không quá 05 ngày làm việc kể từ ngày tiếp nhận đơn | W26: Thời gian xử lý đơn khiếu nại của KH (có báo cáo bằng văn bản) trung bình không quá 05 ngày làm việc kể từ ngày tiếp nhận đơn | Y26: Thời gian xử lý đơn khiếu nại của KH (có báo cáo bằng văn bản) trung bình không quá 05 ngày làm việc kể từ ngày tiếp nhận đơn
B27: 4 | C27: Tỷ lệ phản ánh về chất lượng dịch vụ giảm 5% so với tổng phản ánh năm trước | D27: 0.15 | E27: Tỷ lệ phản ánh về chất lượng dịch vụ giảm 5% so với tổng phản ánh năm trước | G27: Tỷ lệ phản ánh về chất lượng dịch vụ giảm 5% so với tổng phản ánh năm trước | I27: Tỷ lệ phản ánh về chất lượng dịch vụ giảm 5% so với tổng phản ánh năm trước | K27: Tỷ lệ phản ánh về chất lượng dịch vụ giảm 5% so với tổng phản ánh năm trước | O27: Tỷ lệ phản ánh về chất lượng dịch vụ giảm 5% so với tổng phản ánh năm trước | S27: Tỷ lệ phản ánh về chất lượng dịch vụ giảm 5% so với tổng phản ánh năm trước | U27: Tỷ lệ phản ánh về chất lượng dịch vụ giảm 5% so với tổng phản ánh năm trước
B28: 5 | C28: Đảm bảo ≥ 2% khách hàng/tổng số khách hàng được thiết lập hồ sơ quản lý (tính scan hợp đồng để tạo mã dữ liệu KH) | D28: 0.2 | E28: Đảm bảo ≥ 2% khách hàng/tổng số khách hàng được thiết lập hồ sơ quản lý (tính scan hợp đồng để tạo mã dữ liệu KH) | G28: Đảm bảo ≥ 2% khách hàng/tổng số khách hàng được thiết lập hồ sơ quản lý (tính scan hợp đồng để tạo mã dữ liệu KH) | I28: Đảm bảo ≥ 2% khách hàng/tổng số khách hàng được thiết lập hồ sơ quản lý (tính scan hợp đồng để tạo mã dữ liệu KH) | K28: Đảm bảo ≥ 2% khách hàng/tổng số khách hàng được thiết lập hồ sơ quản lý (tính scan hợp đồng để tạo mã dữ liệu KH) | Y28: x
B29: 6 | C29: Tỷ lệ người dùng đăng ký Zalo OA của Công ty đạt ≥ 86% | D29: 0.15 | E29: Tỷ lệ người dùng đăng ký Zalo OA của Xí nghiệp đạt 2% KH còn lại (chưa đk đến thời điểm 30/9) | G29: Tỷ lệ người dùng đăng ký Zalo OA của Xí nghiệp đạt 2% KH còn lại (chưa đk đến thời điểm 30/9) | I29: Tỷ lệ người dùng đăng ký Zalo OA của Xí nghiệp đạt 2% KH còn lại (chưa đk đến thời điểm 30/9) | K29: Tỷ lệ người dùng đăng ký Zalo OA của Xí nghiệp đạt 2% KH còn lại (chưa đk đến thời điểm 30/9) | Y29: Tỷ lệ người dùng đăng ký Zalo OA của Công ty đạt ≥ 86%
C30: PHÁT TRIỂN ĐỔI MỚI | D30: 0.15 | F30: 0.2
B31: 1 | C31: Hoàn thành xây dựng và vận hành hệ thống BSC-KPI trước ngày 31/12/2025 | D31: 0.4 | E31: Hoàn thành xây dựng hệ thống BSC-KPI trước ngày 30/11/2025 | F31: 0.4 | G31: Hoàn thành xây dựng hệ thống BSC-KPI trước ngày 30/11/2025 | I31: Hoàn thành xây dựng hệ thống BSC-KPI trước ngày 30/11/2025 | K31: Hoàn thành xây dựng hệ thống BSC-KPI trước ngày 30/11/2025 | M31: Hoàn thành xây dựng hệ thống BSC-KPI trước ngày 30/11/2025 | O31: Hoàn thành xây dựng hệ thống BSC-KPI trước ngày 30/11/2025 | Q31: Hoàn thành xây dựng hệ thống BSC-KPI trước ngày 30/11/2025 | S31: Hoàn thành xây dựng hệ thống BSC-KPI trước ngày 30/11/2025 | U31: Hoàn thành xây dựng hệ thống BSC-KPI trước ngày 30/11/2025 | W31: Hoàn thành xây dựng hệ thống BSC-KPI trước ngày 30/11/2025 | Y31: Hoàn thành xây dựng hệ thống BSC-KPI trước ngày 30/11/2025
B32: 2 | C32: Đảm bảo có ít nhất 01 sáng kiến cải tiến cấp Công ty | D32: 0.2 | E32: xxx | F32: 0.3 | S32: Đảm bảo có ít nhất 01 sáng kiến cải tiến cấp Công ty
B33: 3 | C33: Tổ chức 03 khóa đào tạo | D33: 0.2 | E33: 100% CBNV (thuộc đối tượng đào tạo) của xí nghiệp tham gia khoá đào tạo do Công ty tổ chức | F33: 0.3 | U33: Tổ chức 03 khóa đào tạo
B34: 4 | C34: Có ít nhất 01 đề tài/dự án phát triển KHCN được ứng dụng | D34: 0.2 | Y34: Có ít nhất 01 đề tài/dự án phát triển KHCN được ứng dụng
C35: TOTAL | D35: =D30+D23+D16+D10 -> 1 | F35: =F30+F23+F16+F10 -> 0.6 | H35: =H30+H23+H16+H10 -> 0 | J35: =J30+J23+J16+J10 -> 0 | L35: =L30+L23+L16+L10 -> 0 | N35: =N30+N23+N16+N10 -> 0 | P35: =P30+P23+P16+P10 -> 0 | R35: =R30+R23+R16+R10 -> 0 | T35: =T30+T23+T16+T10 -> 0 | V35: =V30+V23+V16+V10 -> 0 | X35: =X30+X23+X16+X10 -> 0 | Z35: =Z30+Z23+Z16+Z10 -> 0
B37: Người lập (Prepared by) Xem xét (Checked by) Phê duyệt (Approved by)
B44: Ngày (Date) ....../....../...... Ngày (Date) ....../....../..... Ngày (Date) ....../....../.....

Sheet A7.2.Mục tiêu tổng hợp (SL)
B2: Dự án: | C2: XÂY DỰNG HỆ THỐNG ĐÁNH GIÁ HIỆU QUẢ CÔNG VIỆC
B3: Yêu cầu: | C3: CÔNG TY CỔ PHẦN CẤP NƯỚC ĐÀ NẴNG
B4: Tư vấn: | C4: BrainMark Vietnam
B6: A7.2 | C6: MỤC TIÊU TOÀN CÔNG TY - NĂM 202… | R6: nguyên tắc: không có mục tiêu nào còn lại ở cấp công ty.
E8: 1 | G8: 2 | I8: 3 | K8: 4 | M8: 5 | O8: 6 | Q8: 7 | S8: 8 | U8: 9 | W8: 10 | Y8: 11
B9: Stt | C9: MỤC TIÊU CÔNG TY | D9: TRỌNG SỐ (%) | E9: XÍ NGHIỆP CẤP NƯỚC KV I (Hải Châu - Thanh Khê) | F9: TRỌNG SỐ (%) | G9: XÍ NGHIỆP CẤP NƯỚC KV II (Cẩm Lệ) | H9: TRỌNG SỐ (%) | I9: XÍ NGHIỆP CẤP NƯỚC KV III (Sơn Trà - Ngũ Hành Sơn) | J9: TRỌNG SỐ (%) | K9: XÍ NGHIỆP CẤP NƯỚC KV IV (Liên Chiểu) | L9: TRỌNG SỐ (%) | M9: XÍ NGHIỆP XÂY LẮP | N9: TRỌNG SỐ (%) | O9: TT QUẢN LÝ VẬN HÀNH | P9: TRỌNG SỐ (%) | Q9: BAN KẾ HOẠCH | R9: TRỌNG SỐ (%) | S9: BAN KỸ THUẬT | T9: TRỌNG SỐ (%) | U9: BAN HCNS | V9: TRỌNG SỐ (%) | W9: BAN TCKT | X9: TRỌNG SỐ (%) | Y9: TRUNG TÂM CNTT | Z9: TRỌNG SỐ (%)
C10: VẬN HÀNH (B) | D10: 0.4
B11: 1 | C11: Sản lượng nước sản xuất đạt 122.030.057 m³, tăng 3% so với thực hiện năm trước | D11: 0.15 | G11: 894816 | I11: 1000000 | K11: 913294 | O11: 92658479
B12: 2 | C12: Sản lượng nước tiêu thụ đạt 106.776.300 m³, tăng 3% so với năm trước | D12: 0.3
B13: 3 | C13: Tỷ lệ thất thoát nước không vượt quá 11,33% | D13: 0.3
B14: 4 | C14: Số lượng thay thế đồng hồ đạt 23.824 chiếc/năm | D14: 0.15
B15: 5 | C15: Tỷ lệ khu vực được kiểm soát áp lực nước/tổng khu vực cấp nước đạt 100% | D15: 0.1
C16: TÀI CHÍNH (F) | D16: 0.35
B17: 1 | C17: Doanh thu ngành nước đạt 733,530 tỷ, tăng 15% so với năm trước | D17: 0.15
B18: 2 | C18: Doanh thu ngành xây lắp đạt 3 tỷ | D18: 0.1
B19: 3 | C19: Chỉ tiêu đơn giá nước bình quân đạt 7.020 đồng/m³ | D19: 0.3
B20: 4 | C20: Lợi nhuận trước thuế đạt 161,667 tỷ, tăng 44% so với năm trước | D20: 0.15
B21: 5 | C21: Tỷ lệ công nợ ngành nước/Doanh thu ngành nước không quá 1,4% | D21: 0.1
B22: 6 | C22: Chi phí vận hành (gồm chi phí hoá chất, điện năng)/m³ nước không vượt quá 574 đồng/m³ | D22: 0.2
C23: KHÁCH HÀNG (C) | D23: 0.1
B24: 1 | C24: Số lượng đồng hồ khách hàng đặt mới đạt 7.420 chiếc | D24: 0.2
B25: 2 | C25: Đảm bảo mức độ hài lòng khách hàng được khảo sát đạt ≥ 80% | D25: 0.15
B26: 3 | C26: Thời gian xử lý đơn khiếu nại của KH (có báo cáo bằng văn bản) trung bình không quá 05 ngày làm việc kể từ ngày tiếp nhận đơn | D26: 0.15
B27: 4 | C27: Tỷ lệ phản ánh về chất lượng dịch vụ giảm 5% so với tổng phản ánh năm trước | D27: 0.15
B28: 5 | C28: Đảm bảo ≥ 2% khách hàng/tổng số khách hàng được thiết lập hồ sơ quản lý | D28: 0.2
B29: 6 | C29: Tỷ lệ người dùng đăng ký Zalo OA của Công ty đạt ≥ 86% | D29: 0.15
C30: PHÁT TRIỂN ĐỔI MỚI | D30: 0.15
B31: 1 | C31: Hoàn thành xây dựng và vận hành hệ thống BSC-KPI trước ngày 31/12/2025 | D31: 0.4
B32: 2 | C32: Đảm bảo có ít nhất 01 sáng kiến cải tiến cấp Công ty | D32: 0.2
B33: 3 | C33: Tổ chức 03 khóa đào tạo | D33: 0.2
B34: 4 | C34: Có ít nhất 01 đề tài/dự án phát triển KHCN được ứng dụng | D34: 0.2
C35: TOTAL | D35: =D30+D23+D16+D10 -> 1 | F35: =F30+F23+F16+F10 -> 0 | H35: =H30+H23+H16+H10 -> 0 | J35: =J30+J23+J16+J10 -> 0 | L35: =L30+L23+L16+L10 -> 0 | N35: =N30+N23+N16+N10 -> 0 | P35: =P30+P23+P16+P10 -> 0 | R35: =R30+R23+R16+R10 -> 0 | T35: =T30+T23+T16+T10 -> 0 | V35: =V30+V23+V16+V10 -> 0 | X35: =X30+X23+X16+X10 -> 0 | Z35: =Z30+Z23+Z16+Z10 -> 0
B37: Người lập (Prepared by) Xem xét (Checked by) Phê duyệt (Approved by)
B44: Ngày (Date) ....../....../...... Ngày (Date) ....../....../..... Ngày (Date) ....../....../.....

Sheet A7.3.Mục tiêu Phòng Năm
B2: Dự án: | C2: XÂY DỰNG HỆ THỐNG ĐÁNH GIÁ HIỆU QUẢ CÔNG VIỆC
B3: Yêu cầu: | C3: CÔNG TY CỔ PHẦN CẤP NƯỚC ĐÀ NẴNG
B4: Tư vấn: | C4: BrainMark Vietnam
B6: A7.3 | C6: MỤC TIÊU BAN KẾ HOẠCH- NĂM 2025
B9: Stt | C9: MỤC TIÊU CÔNG TY | D9: TRỌNG SỐ (%) | E9: BAN HCNS | F9: TRỌNG SỐ (%)
C10: VẬN HÀNH (B) | D10: 0.4 | F10: 0.4
B11: 1 | C11: Sản lượng nước sản xuất đạt 122.030.057 m³, tăng 3% so với thực hiện năm trước | D11: 0.15 | E11: Hoàn thành 95% công việc theo Ban Tổng giám đốc giao trong cuộc họp giao ban | F11: 0.2
B12: 2 | C12: Sản lượng nước tiêu thụ đạt 106.776.300 m³, tăng 3% so với năm trước | D12: 0.3 | E12: Tỷ lệ văn bản, hồ sơ xử lý đúng hạn sau khi tiếp nhận văn bản ≥ 95% /tổng số lượng văn bản văn phòng điện tử tiếp nhận | F12: 0.2
B13: 3 | C13: Tỷ lệ thất thoát nước không vượt quá 11,33% | D13: 0.3 | E13: Đảm bảo 100%công văn đi đến được xử lý đúng hạn (tại giai đoạn theo chức năng Ban HCNS) | F13: 0.2
B14: 4 | C14: Số lượng thay thế đồng hồ đạt 23.824 chiếc/năm | D14: 0.15 | E14: Đảm bảo tuân thủ 100% chế độ chính sách quy định Luật Lao động (HĐLĐ, Chế độ nghỉ hưu, nghỉ trước tuổi, nâng lương,…) | F14: 0.15
B15: 5 | C15: Tỷ lệ khu vực được kiểm soát áp lực nước/tổng khu vực cấp nước đạt 100% | D15: 0.1 | E15: Đảm bảo trình phê duyệt kế hoạch lao động tiền lương và quyết toán tiền lương năm trước 20/03 hàng năm | F15: 0.25
C17: TÀI CHÍNH (F) | D17: 0.35 | F17: 0.3
B18: 1 | C18: Doanh thu ngành nước đạt 733,530 tỷ, tăng 15% so với năm trước | D18: 0.15 | E18: Chi phí Văn phòng phẩm (bộ phận văn phòng công ty) giảm 5% so với năm 2024 | F18: 0.4
B19: 2 | C19: Doanh thu ngành xây lắp đạt 3 tỷ | D19: 0.1 | E19: Kinh phí Đào tạo không vượt quá kế hoạch được duyệt trong năm | F19: 0.4
B20: 3 | C20: Chỉ tiêu đơn giá nước bình quân đạt 7.020 đồng/m³ | D20: 0.3 | E20: Tiết kiệm chi phí hành chính thường xuyên (văn phòng phẩm, điện nước) ≥ 5% so với năm 2024 | F20: 0.2
B21: 4 | C21: Lợi nhuận trước thuế đạt 161,667 tỷ, tăng 44% so với năm trước | D21: 0.15
B22: 5 | C22: Số dư công nợ ngành nước/Doanh thu ngành nước không quá 1,7% | D22: 0.1
B23: 6 | C23: Chi phí vận hành (gồm chi phí hoá chất, điện năng)/m³ nước không vượt quá 580 đồng/m³ | D23: 0.2
C24: KHÁCH HÀNG (C) | D24: 0.1 | F24: 0.15
B25: 1 | C25: Số lượng đồng hồ khách hàng đặt mới đạt 7.420 chiếc | D25: 0.2 | E25: Không có phàn nàn của khách hàng về thái độ tiếp xúc, chăm sóc khách hàng của Bộ phận Call Center | F25: 0.25
B26: 2 | C26: Đảm bảo mức độ hài lòng khách hàng được khảo sát đạt ≥ 80% | D26: 0.15 | E26: Đảm bảo hoàn thành khảo sát mức độ hài lòng của khách hàng (theo chủ trương của HĐQT) | F26: 0.15
B27: 3 | C27: Thời gian xử lý đơn khiếu nại của KH (có báo cáo bằng văn bản) trung bình không quá 05 ngày làm việc kể từ ngày tiếp nhận đơn | D27: 0.15 | E27: Thời gian xử lý đơn khiếu nại của KH (có báo cáo bằng văn bản) trung bình không quá 05 ngày làm việc kể từ ngày tiếp nhận đơn | F27: 0.2
B28: 4 | C28: Tỷ lệ phản ánh về chất lượng dịch vụ giảm 5% so với tổng phản ánh năm trước | D28: 0.15 | E28: Tỷ lệ phản ánh về chất lượng dịch vụ giảm 5% so với tổng phản ánh năm trước | F28: 0.15
B29: 5 | C29: Đảm bảo ≥ 2% khách hàng/tổng số khách hàng được thiết lập hồ sơ quản lý (tính scan hợp đồng để tạo mã dữ liệu KH) | D29: 0.2 | E29: Đảm bảo 40% hồ sơ (hồ sơ nhân sự ) được số hoá | F29: 0.25
B30: 6 | C30: Tỷ lệ người dùng đăng ký Zalo OA của Công ty đạt ≥ 86% | D30: 0.15
C31: PHÁT TRIỂN | D31: 0.15 | F31: 0.15
B32: 1 | C32: Hoàn thành xây dựng và vận hành hệ thống BSC-KPI trước ngày 31/12/2025 | D32: 0.4 | E32: Hoàn thành xây dựng và vận hành hệ thống BSC-KPI trước ngày 31/12/2025 | F32: 0.4
B33: 2 | C33: Đảm bảo có ít nhất 01 sáng kiến cải tiến cấp Công ty | D33: 0.2 | E33: Hoàn thành việc xây dựng lại đơn giá tiền lương và hệ số lương của Biên đọc (nhằm nâng cao NSLĐ) trình HĐ lương trước 31/12/2025 | F33: 0.15
B34: 3 | C34: Tổ chức 03 khóa đào tạo | D34: 0.2 | E34: Tổ chức 03 khóa đào tạo | F34: 0.2
B35: 4 | C35: Có ít nhất 01 đề tài/dự án phát triển KHCN được ứng dụng | D35: 0.2 | E35: Hoàn thành xây dựng 50 tình huống xử lý cho Chatbot AI Dawaco | F35: 0.25
C37: TOTAL | D37: =SUM(D10+D17+D24+D31) -> 1 | F37: =SUM(F10+F17+F24+F31) -> 1
B39: Người lập (Prepared by) Xem xét (Checked by) Phê duyệt (Approved by)
B46: Ngày (Date) ....../....../...... Ngày (Date) ....../....../..... Ngày (Date) ....../....../.....

Sheet Mục tiêu c Chi phân bổ
B2: Dự án: | C2: XÂY DỰNG HỆ THỐNG ĐÁNH GIÁ HIỆU QUẢ CÔNG VIỆC
B3: Yêu cầu: | C3: CÔNG TY CỔ PHẦN CẤP NƯỚC ĐÀ NẴNG
B4: Tư vấn: | C4: BrainMark Vietnam
B6: A7.9 | C6: KPI BAN HCNS - NĂM 2026
N7: Q1 | O7: Q2 | P7: Q3 | Q7: Q4
B9: STT | C9: Mục tiêu | D9: Trọng số (%) | E9: Tiêu chí đánh giá | F9: Phương pháp đo | G9: Thời điểm ghi nhận | H9: Nguồn chứng minh | I9: ĐVT | J9: Kế hoạch (KH) | K9: Thực hiện (TH) | L9: Hoàn thành | M9: Kết quả KPI | N9: Mục tiêu
C10: VẬN HÀNH (B) | D10: 0.4 | M10: 0 | N10: VẬN HÀNH (B)
B11: 1 | C11: Hoàn thành 95% các công việc theo phiếu giao việc, thông báo họp giao ban và thông báo khác của Ban Tổng giám đốc giao | D11: 0.2 | E11: Tỷ lệ hoàn thành các công việc theo Ban TGĐ giao (trong cuộc họp giao ban) thực tế | F11: TH ≥ KH, KPI = 100% TH < KH, KPI = 0 | G11: 46387 | H11: Ban Kế hoạch chủ trì, phối hợp với Ban TCKT, Ban HCNS, Ban Kỹ thuật,… | I11: % | J11: 0.95 | L11: =IF(LEN(K11)=0,"",IF(K11>=J11,100%,0%)) | M11: =IFERROR(L11*D11,"") | N11: Hoàn thành 95% các công việc theo phiếu giao việc, thông báo họp giao ban và thông báo khác của Ban Tổng giám đốc giao | O11: Hoàn thành 95% các công việc theo phiếu giao việc, thông báo họp giao ban và thông báo khác của Ban Tổng giám đốc giao | P11: Hoàn thành 95% các công việc theo phiếu giao việc, thông báo họp giao ban và thông báo khác của Ban Tổng giám đốc giao | Q11: Hoàn thành 95% các công việc theo phiếu giao việc, thông báo họp giao ban và thông báo khác của Ban Tổng giám đốc giao
B12: 2 | C12: Tỷ lệ văn bản, hồ sơ xử lý đúng hạn sau khi tiếp nhận văn bản ≥ 90%/tổng số lượng văn bản văn phòng điện tử tiếp nhận | D12: 0.2 | E12: Tỷ lệ văn bản, hồ sơ xử lý đúng hạn sau khi tiếp nhận văn bản/tổng số lượng văn bản văn phòng điện tử tiếp nhận thực tế | F12: TH < 80%: KPI= 0 TH ≥ 80%: TH/KH*100% Max KPI = 120% | G12: 46387 | H12: Ban HCNS báo cáo, Ban kế hoạch xác nhận | I12: % | J12: 0.9 | L12: =IF(LEN(K12)=0,"",IF(K12<80%,0,MIN(120%,K12/J12*100%))) | M12: =IFERROR(L12*D12,"") | N12: Tỷ lệ văn bản, hồ sơ xử lý đúng hạn sau khi tiếp nhận văn bản ≥ 90%/tổng số lượng văn bản văn phòng điện tử tiếp nhận | O12: Tỷ lệ văn bản, hồ sơ xử lý đúng hạn sau khi tiếp nhận văn bản ≥ 90%/tổng số lượng văn bản văn phòng điện tử tiếp nhận | P12: Tỷ lệ văn bản, hồ sơ xử lý đúng hạn sau khi tiếp nhận văn bản ≥ 90%/tổng số lượng văn bản văn phòng điện tử tiếp nhận | Q12: Tỷ lệ văn bản, hồ sơ xử lý đúng hạn sau khi tiếp nhận văn bản ≥ 90%/tổng số lượng văn bản văn phòng điện tử tiếp nhận
B13: 3 | C13: Đảm bảo 100% công văn đi đến được xử lý đúng hạn (tại giai đoạn theo chức năng Ban HCNS) | D13: 0.2 | E13: Số lần công văn đi đến xử lý trễ hạn (tại giai đoạn theo chức năng Ban HCNS) thực tế | F13: TH = 0, KPI = 100% TH ≥ 1, KPI = 0% | G13: 46387 | H13: Báo cáo của Ban HCNS | I13: Lần | J13: 0 | L13: =IF(LEN(K13)=0,"",IF(K13=J13,1,0)) | M13: =IFERROR(L13*D13,"") | N13: Đảm bảo 100% công văn đi đến được xử lý đúng hạn (tại giai đoạn theo chức năng Ban HCNS) | O13: Đảm bảo 100% công văn đi đến được xử lý đúng hạn (tại giai đoạn theo chức năng Ban HCNS) | P13: Đảm bảo 100% công văn đi đến được xử lý đúng hạn (tại giai đoạn theo chức năng Ban HCNS) | Q13: Đảm bảo 100% công văn đi đến được xử lý đúng hạn (tại giai đoạn theo chức năng Ban HCNS)
B14: 4 | C14: Đảm bảo tuân thủ 100% chế độ chính sách quy định Luật Lao động (HĐLĐ, Chế độ nghỉ hưu, nghỉ trước tuổi, nâng lương,…) | D14: 0.15 | E14: Số lần vi phạm thực hiện chế độ chính sách quy định Luật Lao động (HĐLĐ, Chế độ nghỉ hưu, nghỉ trước tuổi, nâng lương,…) | F14: TH = 0, KPI = 100% TH ≥ 1, KPI = 0% | G14: 46387 | H14: Báo cáo của Ban HCNS, Ban TCKT xác nhận | I14: Lần | J14: 0 | L14: =IF(LEN(K14)=0,"",IF(K14=J14,1,0)) | M14: =IFERROR(L14*D14,"") | N14: Đảm bảo tuân thủ 100% chế độ chính sách quy định Luật Lao động (HĐLĐ, Chế độ nghỉ hưu, nghỉ trước tuổi, nâng lương,…) | O14: Đảm bảo tuân thủ 100% chế độ chính sách quy định Luật Lao động (HĐLĐ, Chế độ nghỉ hưu, nghỉ trước tuổi, nâng lương,…) | P14: Đảm bảo tuân thủ 100% chế độ chính sách quy định Luật Lao động (HĐLĐ, Chế độ nghỉ hưu, nghỉ trước tuổi, nâng lương,…) | Q14: Đảm bảo tuân thủ 100% chế độ chính sách quy định Luật Lao động (HĐLĐ, Chế độ nghỉ hưu, nghỉ trước tuổi, nâng lương,…)
B15: 5 | C15: Đảm bảo trình HĐQT phê duyệt kế hoạch lao động tiền lương và quyết toán tiền lương năm trước trước 31/3/2026 | D15: 0.25 | E15: Thời gian thực tế trình phê duyệt kế hoạch lao động tiền lương và quyết toán tiền lương năm trước | F15: TH ≤ KH, KPI = 100% TH > KH, KPI = 0% | G15: 46112 | H15: Báo cáo của Ban HCNS, Ban TCKT xác nhận | I15: Ngày | J15: 46112 | L15: =IF(LEN(K15)=0,"",IF(K15<=J15,1,0)) | M15: =IFERROR(L15*D15,"") | N15: Đảm bảo trình HĐQT phê duyệt kế hoạch lao động tiền lương và quyết toán tiền lương năm trước trước 31/3/2026
C16: TÀI CHÍNH (F) | D16: 0.25 | M16: 0 | N16: TÀI CHÍNH (F)
B17: 1 | C17: Chi phí Văn phòng phẩm (bộ phận văn phòng công ty) giảm 2% so với năm trước | D17: 0.4 | E17: Tỷ lệ chi phí VVP (bộ phận VP Công ty) giảm so với năm 2025 thực tế | F17: TH ≥ KH: KPI = TH/KH*100% TH < KH: KPI = 0% Max KPI = 120% | G17: 46387 | H17: Ban TCKT xác nhận | I17: % | J17: 0.02 | L17: =IF(LEN(K17)=0,"",MAX(0%,IF(K17<J17,0,(MIN(120%,K17/J17*100%))))) | M17: =IFERROR(L17*D17,"") | N17: Chi phí Văn phòng phẩm (bộ phận văn phòng công ty) giảm 2% so với quý 1 năm trước | O17: Chi phí Văn phòng phẩm (bộ phận văn phòng công ty) giảm 2% so với quý 2 năm trước | P17: Chi phí Văn phòng phẩm (bộ phận văn phòng công ty) giảm 2% so với quý 3 năm trước | Q17: Chi phí Văn phòng phẩm (bộ phận văn phòng công ty) giảm 2% so với quý năm trước
B18: 2 | C18: Kinh phí Đào tạo không vượt quá kế hoạch được duyệt trong năm | D18: 0.4 | E18: Tỷ lệ kinh phí đào tạo so với kế hoạch đào tạo được duyệt trong năm thực tế | F18: TH <= KH: KPI = 100% TH > KH: KPI =0% | G18: 46387 | H18: Báo cáo của Ban HCNS, Ban TCKT xác nhận | I18: % | J18: 1 | L18: =IF(LEN(K18)=0,"",IF(K18<=J18,1,0)) | M18: =IFERROR(L18*D18,"") | O18: Kinh phí Đào tạo không vượt quá kế hoạch được duyệt trong năm | P18: Kinh phí Đào tạo không vượt quá kế hoạch được duyệt trong năm
B19: 3 | C19: Tiết kiệm điện năng tiêu hao trong năm (VPCT) ≥ 5% so với năm trước | D19: 0.2 | E19: Tỷ lệ tiết kiệm chi phí hành chính thường xuyên (VVP, điện nước) so với năm 2025 thực tế | F19: TH ≥ KH: KPI = TH/KH*100% 0<TH < KH: KPI = TH/KH*100% Max KPI = 120% | G19: 46387 | H19: Báo cáo của Ban HCNS, Ban TCKT xác nhận | I19: % | J19: 0.05 | L19: =IF(LEN(K19)=0,"",MAX(0%,IF(K19<J19,K19/J19*100%,(MIN(120%,K19/J19*100%))))) | M19: =IFERROR(L19*D19,"") | N19: Sản lượng tiêu thụ điện Q1 không cao hơn Q1 năm trước | O19: Sản lượng tiêu thụ điện Q2 không cao hơn Q2 năm trước | P19: Sản lượng tiêu thụ điện Q3 không cao hơn Q13năm trước | Q19: Sản lượng tiêu thụ điện Q4 không cao hơn Q4 năm trước
C20: KHÁCH HÀNG (C) | D20: 0.15 | M20: 0 | N20: KHÁCH HÀNG (C)
B21: 1 | C21: Không quá 4 lần phàn nàn của khách hàng về thái độ tiếp xúc, chăm sóc khách hàng của Bộ phận Call Center | D21: 0.25 | E21: Số lần phàn nàn của khách hàng về thái độ tiếp xúc, chăm sóc khách hàng của Bộ phận Call Center | F21: TH ≤ KH: KPI = 100% TH > KH: KPI = 0% | G21: 46387 | H21: Ban HCNS xác nhận | I21: Lần | J21: 4 | L21: =IF(LEN(K21)=0,"",IF(K21<=J21,1,0)) | M21: =IFERROR(L21*D21,"") | N21: Không quá 1 lần phàn nàn của khách hàng về thái độ tiếp xúc, chăm sóc khách hàng của Bộ phận Call Center | O21: Không quá 1 lần phàn nàn của khách hàng về thái độ tiếp xúc, chăm sóc khách hàng của Bộ phận Call Center | P21: Không quá 1 lần phàn nàn của khách hàng về thái độ tiếp xúc, chăm sóc khách hàng của Bộ phận Call Center | Q21: Không quá 1 lần phàn nàn của khách hàng về thái độ tiếp xúc, chăm sóc khách hàng của Bộ phận Call Center
B22: 2 | C22: Đảm bảo hoàn thành khảo sát mức độ hài lòng của khách hàng (theo chủ trương của HĐQT) | D22: 0.15 | E22: Số lần chậm trễ hoàn thành khoả sát mức độ hài lòng của khách hàng (theo chủ trương của HĐQT) thực tế | F22: TH = 0, KPI = 100% TH ≥ 1, KPI = 0% | G22: 46112 | H22: TTCNTT xác nhận | I22: Ngày | J22: 46112 | L22: =IF(LEN(K22)=0,"",IF(K22=J22,1,0)) | M22: =IFERROR(L22*D22,"") | O22: Đảm bảo hoàn thành khảo sát mức độ hài lòng của khách hàng (theo chủ trương của HĐQT) | P22: Đảm bảo hoàn thành khảo sát mức độ hài lòng của khách hàng (theo chủ trương của HĐQT)
B23: 3 | C23: Thời gian xử lý đơn khiếu nại của KH (có báo cáo bằng văn bản) trung bình không quá 05 ngày làm việc kể từ ngày tiếp nhận đơn | D23: 0.2 | E23: Trung bình thời gian xử lý đơn khiếu nại của KH (có báo cáo bằng văn bản) kể từ ngày tiếp nhận đơn | F23: TH ≤ KH: KPI = KH/TH*100% TH > KH: KPI = 0% Max KPI = 120% | G23: 46387 | H23: HCNS báo cáo, các XN liên quan xác nhận | I23: Ngày | J23: 5 | L23: =IF(LEN(K23)=0,"",IF(K23>J23,0,MIN(120%,J23/K23*100%))) | M23: =IFERROR(L23*D23,"") | N23: Thời gian xử lý đơn khiếu nại của KH (có báo cáo bằng văn bản) trung bình không quá 05 ngày làm việc kể từ ngày tiếp nhận đơn | O23: Thời gian xử lý đơn khiếu nại của KH (có báo cáo bằng văn bản) trung bình không quá 05 ngày làm việc kể từ ngày tiếp nhận đơn | P23: Thời gian xử lý đơn khiếu nại của KH (có báo cáo bằng văn bản) trung bình không quá 05 ngày làm việc kể từ ngày tiếp nhận đơn | Q23: Thời gian xử lý đơn khiếu nại của KH (có báo cáo bằng văn bản) trung bình không quá 05 ngày làm việc kể từ ngày tiếp nhận đơn
B24: 4 | C24: Tỷ lệ phản ánh về chất lượng dịch vụ giảm 5% so với tổng phản ánh năm trước | D24: 0.15 | E24: Tỷ lệ giảm phản ánh về chất lượng dịch vụ so với tổng số phản ánh năm trước | F24: TH ≥ 80%KH: KPI = TH/KH*100% TH < 80%KH: KPI = 0% Max KPI = 120% | G24: 46387 | H24: HCNS báo cáo, các XN liên quan xác nhận | I24: % | J24: 0.05 | L24: =IF(LEN(K24)=0,"",IF(K24<J24*80%,0,MIN(120%,K24/J24*100%))) | M24: =IFERROR(L24*D24,"") | N24: Tỷ lệ phản ánh về chất lượng dịch vụ giảm 5% so với tổng phản ánh quý 1 năm trước | O24: Tỷ lệ phản ánh về chất lượng dịch vụ giảm 5% so với tổng phản ánh quý 1 năm trước | P24: Tỷ lệ phản ánh về chất lượng dịch vụ giảm 5% so với tổng phản ánh quý 1 năm trước | Q24: Tỷ lệ phản ánh về chất lượng dịch vụ giảm 5% so với tổng phản ánh quý 1 năm trước
B25: 5 | C25: Đảm bảo 80% hồ sơ (hồ sơ nhân sự) được số hoá trước 31/12/2026 | D25: 0.25 | E25: Tỷ lệ hồ sơ (hồ sơ nhân sự) được số hoá thực tế | F25: TH < KH: KPI = 0% TH ≥ KH: KPI = TH/KH*100% | G25: 46387 | H25: TT CNTT xác nhận | I25: % | J25: 0.8 | L25: =IF(LEN(K25)=0,"",IF(K25<J25,0,MIN(120%,K25/J25*100%))) | M25: =IFERROR(L25*D25,"") | N25: Đảm bảo 20% hồ sơ (hồ sơ nhân sự) được số hoá trước 31/03/2026 | O25: Đảm bảo 20% hồ sơ (hồ sơ nhân sự) được số hoá trước 31/03/2026 | P25: Đảm bảo 20% hồ sơ (hồ sơ nhân sự) được số hoá trước 31/03/2026 | Q25: Đảm bảo 20% hồ sơ (hồ sơ nhân sự) được số hoá trước 31/03/2026
C26: PHÁT TRIỂN (L) | D26: 0.2 | M26: 0 | N26: PHÁT TRIỂN (L)
B27: 1 | C27: Hoàn thành xây dựng hệ thống lương 3P trước ngày 31/12/2026 | D27: 0.4 | E27: Thời gian hoàn thành xây dựng và vận hành hệ thống lương 3P | F27: TH ≤ KH, KPI = 100% TH > KH, KPI = 0% | G27: 46387 | H27: Ban KPI | I27: Ngày | J27: 46387 | L27: =IF(LEN(K27)=0,"",IF(K27<=J27,1,0)) | M27: =IFERROR(L27*D27,"") | N27: Thời gian hoàn thành xây dựng và vận hành hệ thống lương 3P | O27: Thời gian hoàn thành xây dựng và vận hành hệ thống lương 3P
B28: 2 | C28: Hoàn thành việc xây dựng lại đơn giá tiền lương và hệ số lương của Biên đọc (nhằm nâng cao NSLĐ) HĐ lương phê duyệt trước 31/12/2026 | D28: 0.15 | E28: Thời gian hoàn thành việc xây dựng lại đơn giá tiền lương và hệ số lương của Biên đọc (nhằm nâng cao NSLĐ) trình HĐ lương thực tế | F28: TH ≤ KH, KPI = 100% TH > KH, KPI = 0% | G28: 46387 | H28: Hội đồng lương | I28: Ngày | J28: 46387 | L28: =IF(LEN(K28)=0,"",IF(K28<=J28,1,0)) | M28: =IFERROR(L28*D28,"") | N28: ='[1]A7.4.Mục tiêu Phòng Q1.26'!P27 -> #REF! | O28: Hoàn thành việc xây dựng lại đơn giá tiền lương và hệ số lương của Biên đọc (nhằm nâng cao NSLĐ) HĐ lương phê duyệt trước 31/12/2026 | P28: Hoàn thành việc xây dựng lại đơn giá tiền lương và hệ số lương của Biên đọc (nhằm nâng cao NSLĐ) HĐ lương phê duyệt trước 31/12/2026
B29: 3 | C29: Tổ chức 03 khóa đào tạo | D29: 0.2 | E29: Số khoá đào tạo được tổ chức | F29: TH ≥ KH, KPI = 100% TH < KH, KPI = 0 | G29: 46387 | H29: HCNS báo cáo, Ban Kế hoạch xác nhận | I29: Khoá đào tạo | J29: 3 | L29: =IF(LEN(K29)=0,"",IF(K29>=J29,100%,0%)) | M29: =IFERROR(L29*D29,"") | N29: ='[1]A7.4.Mục tiêu Phòng Q1.26'!P28 -> 0 | O29: Tổ chức 01 khóa đào tạo | P29: Tổ chức 02 khóa đào tạo
B30: 4 | C30: Ứng dụng AI trong việc lập Kết luận giao ban hàng tháng | D30: 0.25 | E30: Số lần ứng dụng AI trong việc lập Kết luận giao ban hàng tháng | F30: TH ≥ KH, KPI = 100% TH < KH, KPI = 0 | G30: 46387 | H30: TT CNTT xác nhận | I30: Lần | J30: 1 | L30: =IF(LEN(K30)=0,"",IF(K30>=J30,100%,0%)) | M30: =IFERROR(L30*D30,"") | N30: ='[1]A7.4.Mục tiêu Phòng Q1.26'!P29 -> 0 | P30: Ứng dụng AI trong việc lập Kết luận giao ban hàng tháng
B31: TỔNG: | D31: 1 | M31: 0
C33: Người lập | F33: Giám đốc đơn vị | J33: Phê duyệt
C40: Ngày (Date) ....../....../...... | F40: Ngày (Date) ....../....../...... | K40: Ngày (Date) ....../....../......

Sheet A7.5.Mục tiêu Phòng Tháng
B2: Dự án: | C2: XÂY DỰNG HỆ THỐNG ĐÁNH GIÁ HIỆU QUẢ CÔNG VIỆC
B3: Yêu cầu: | C3: CÔNG TY CỔ PHẦN CẤP NƯỚC ĐÀ NẴNG
B4: Tư vấn: | C4: BrainMark Vietnam
B6: A7.5 | C6: MỤC TIÊU BAN ….. - THÁNG/NĂM 202….
B9: Stt | C9: MỤC TIÊU PHÒNG … NĂM 202…. | D9: TRỌNG SỐ (%) | E9: THÁNG 1 | F9: THÁNG 2 | G9: THÁNG 3 | H9: THÁNG 4 | I9: THÁNG 5 | J9: THÁNG 6 | K9: THÁNG 7 | L9: THÁNG 8 | M9: THÁNG 9 | N9: THÁNG 10 | O9: THÁNG 11 | P9: THÁNG 12
C10: TÀI CHÍNH (F)
B11: 1
B12: 2
B13: 3
B14: 4
B15: 5
C16: KHÁCH HÀNG (C)
B17: 1
B18: 2
B19: 3
B20: 4
B21: 5
C22: VẬN HÀNH (B)
B23: 1
B24: 2
B25: 3
B26: 4
B27: 5
C28: PHÁT TRIỂN (L)
B29: 1
B30: 2
B31: 3
B32: 4
B33: 5
C34: TOTAL | D34: =D10+D16+D22+D28 -> 0
C36: Người lập (Prepared by) | E36: Xem xét (Checked by) | M36: Phê duyệt (Approved by)
C43: Ngày (Date) ....../....../...... | E43: Ngày (Date) ....../....../...... | M43: Ngày (Date) ....../....../......

Sheet A7.8.KPI Cong ty Nam 2025
B2: Dự án: | C2: XÂY DỰNG HỆ THỐNG ĐÁNH GIÁ HIỆU QUẢ CÔNG VIỆC
B3: Yêu cầu: | C3: CÔNG TY CỔ PHẦN CẤP NƯỚC ĐÀ NẴNG
B4: Tư vấn: | C4: BrainMark Vietnam
B6: A7.8 | C6: KPI CÔNG TY NĂM 2025
B8: STT | C8: Mục tiêu | D8: Trọng số (%) | E8: Tiêu chí đánh giá (TH) | F8: Phương pháp đo | G8: Thời điểm ghi nhận | H8: Nguồn chứng minh | I8: ĐVT | J8: Kế hoạch (KH) | K8: Thực hiện (TH) | L8: Hoàn thành | M8: KẾT QUẢ KPI
C9: VẬN HÀNH (B) | D9: 0.4 | M9: =SUM(M10:M14)*D9 -> 0.40165015
B10: 1 | C10: Sản lượng nước sản xuất đạt 122.030.057 m³, tăng 3% so với thực hiện năm trước | D10: 0.15 | E10: Tổng sản lượng nước sản xuất thực tế (bao gồm sản lượng Hoà Liên) | F10: TH ≥ 80%KH: KPI = TH/KH*100% TH < 80%KH: KPI = 0% Max KPI = 120% | G10: 46022 | H10: Báo cáo của B.KH | I10: m³ | J10: 122030057 | K10: 122050000 | L10: =IF(LEN(K10)=0,"",IF(K10<J10*80%,0,MIN(120%,K10/J10*100%))) -> 1.0001634 | M10: =IFERROR(L10*D10,"") -> 0.15002451
B11: 2 | C11: Sản lượng nước tiêu thụ đạt 106.776.300 m³, tăng 3% so với năm trước | D11: 0.3 | E11: Tổng sản lượng nước tiêu thụ thực tế | F11: TH ≥ 95%KH: KPI = TH/KH*100% TH < 95%KH: KPI = 0% Max KPI = 120% | G11: 46022 | H11: Báo cáo của B.TCKT | I11: m³ | J11: 106776300 | K11: 107952410 | L11: =IF(LEN(K11)=0,"",IF(K11<J11*95%,0,MIN(120%,K11/J11*100%))) -> 1.0110147 | M11: =IFERROR(L11*D11,"") -> 0.30330441
B12: 3 | C12: Tỷ lệ thất thoát nước không vượt quá 11,33% | D12: 0.3 | E12: Tỷ lệ thất thoát nước thực tế | F12: TH ≤ KH: KPI = KH/TH*100% TH > KH: KPI = 0% Max KPI = 120% | G12: 46022 | H12: Báo cáo của TTQLVH | I12: % | J12: 0.1133 | K12: 0.113 | L12: =IF(LEN(K12)=0,"",IF(K12>J12,0,MIN(120%,J12/K12*100%))) -> 1.0026549 | M12: =IFERROR(L12*D12,"") -> 0.30079646
B13: 4 | C13: Số lượng thay thế đồng hồ đạt 23.824 chiếc/năm | D13: 0.15 | E13: Số lượng đồng hồ thay thế thực tế | F13: TH ≥ KH, KPI = 100% TH < KH, KPI = 0 | G13: 46022 | H13: Báo cáo của B.TCKT | I13: Chiếc | J13: 23824 | K13: 24100 | L13: =IF(LEN(K13)=0,"",IF(K13>=J13,100%,0%)) -> 1 | M13: =IFERROR(L13*D13,"") -> 0.15
B14: 5 | C14: Tỷ lệ khu vực được kiểm soát áp lực nước/tổng khu vực cấp nước đạt 100% | D14: 0.1 | E14: Tỷ lệ khu vực được kiểm soát áp lực nước / tổng khu vực cấp nước | F14: TH ≥ 90%KH: KPI = TH/KH*100% TH < 90%KH: KPI = 0% Max KPI = 120% | G14: 46022 | H14: Báo cáo của TTQLVH | I14: % | J14: 1 | K14: 1 | L14: =IF(LEN(K14)=0,"",IF(K14<J14*90%,0,MIN(120%,K14/J14*100%))) -> 1 | M14: =IFERROR(L14*D14,"") -> 0.1
C15: TÀI CHÍNH (F) | D15: 0.35 | M15: =SUM(M16:M21)*D15 -> 0.38595884
B16: 1 | C16: Doanh thu ngành nước đạt 733,530 tỷ, tăng 15% so với năm trước | D16: 0.15 | E16: Doanh thu ngành nước thực tế | F16: TH ≥ KH: KPI = TH/KH*100% TH < KH: KPI = 0% Max KPI = 120% | G16: 46022 | H16: Báo cáo của B.TCKT | I16: Tỷ | J16: 733.53 | K16: 809211620187 | L16: =IF(LEN(K16)=0,"",IF(K16<J16,0,MIN(120%,K16/J16*100%))) -> 1.2 | M16: =IFERROR(L16*D16,"") -> 0.18
B17: 2 | C17: Doanh thu ngành xây lắp đạt 3 tỷ | D17: 0.1 | E17: Doanh thu ngành xây lắp thực tế | F17: TH ≥ 80%KH: KPI = TH/KH*100% TH < 80%KH: KPI = 0% Max KPI = 120% | G17: 46022 | H17: Báo cáo của B.TCKT | I17: Tỷ | J17: 3 | K17: 3.5 | L17: =IF(LEN(K17)=0,"",IF(K17<J17*80%,0,MIN(120%,K17/J17*100%))) -> 1.1666667 | M17: =IFERROR(L17*D17,"") -> 0.11666667
B18: 3 | C18: Chỉ tiêu đơn giá nước bình quân đạt 7.020 đồng/m³ | D18: 0.3 | E18: Chỉ tiêu đơn giá nước bình quân trong năm | F18: TH ≥ KH, KPI = TH/KH*100% TH < KH, KPI = 0 Max KPI = 120% | G18: 46022 | H18: Báo cáo của B.TCKT | I18: đồng/m³ | J18: 7020 | K18: 7080 | L18: =IF(LEN(K18)=0,"",IF(K18<J18,0,MIN(120%,K18/J18*100%))) -> 1.008547 | M18: =IFERROR(L18*D18,"") -> 0.3025641
B19: 4 | C19: Lợi nhuận trước thuế đạt 161,667 tỷ, tăng 44% so với năm trước | D19: 0.15 | E19: Lợi nhuận trước thuế thực tế | F19: TH ≥ KH: KPI = TH/KH*100% TH < KH: KPI = 0% Max KPI = 120% | G19: 46022 | H19: Báo cáo của B.TCKT | I19: Tỷ | J19: 161.667 | K19: 230 | L19: =IF(LEN(K19)=0,"",IF(K19<J19,0,MIN(120%,K19/J19*100%))) -> 1.2 | M19: =IFERROR(L19*D19,"") -> 0.18
B20: 5 | C20: Số dư công nợ ngành nước/Doanh thu ngành nước không quá 1,7% | D20: 0.1 | E20: Số dư công nợ so với doanh thu (chỉ tính ngành nước) | F20: TH ≤ KH: KPI = KH/TH*100% TH > KH: KPI = 0% Max KPI = 120% | G20: 46022 | H20: Báo cáo của B.TCKT | I20: % | J20: 0.017 | K20: 0.014 | L20: =IF(LEN(K20)=0,"",IF(K20>J20,0,MIN(120%,J20/K20*100%))) -> 1.2 | M20: =IFERROR(L20*D20,"") -> 0.12
B21: 6 | C21: Chi phí vận hành (gồm chi phí hoá chất, điện năng)/m³ nước không vượt quá 580 đồng/m³ | D21: 0.2 | E21: Chi phí vận hành thực tế (gồm chi phí hoá chất & điện năng)/m³ nước (Không tính Hoà Liên) | F21: TH ≤ KH: KPI = KH/TH*100% TH > KH: KPI = 0% Max KPI = 120% | G21: 46022 | H21: Báo cáo của B.TCKT | I21: đồng/m³ | J21: 580 | K21: 570 | L21: =IF(LEN(K21)=0,"",IF(K21>J21,0,MIN(120%,J21/K21*100%))) -> 1.0175439 | M21: =IFERROR(L21*D21,"") -> 0.20350877
C22: KHÁCH HÀNG (C) | D22: 0.1 | K22: 8050 | M22: =SUM(M23:M28)*D22 -> 0.10269811
B23: 1 | C23: Số lượng đồng hồ khách hàng đặt mới đạt 7.420 chiếc | D23: 0.2 | E23: Số lượng đồng hồ đặt mới | F23: TH ≥ 80%KH: KPI = TH/KH*100% TH < 80%KH: KPI = 0% Max KPI = 120% | G23: 46022 | H23: Báo cáo của B.TCKT | I23: Chiếc | J23: 7420 | K23: 8050 | L23: =IF(LEN(K23)=0,"",IF(K23<J23*80%,0,MIN(120%,K23/J23*100%))) -> 1.0849057 | M23: =IFERROR(L23*D23,"") -> 0.21698113
B24: 2 | C24: Đảm bảo mức độ hài lòng khách hàng được khảo sát đạt ≥ 80% | D24: 0.15 | E24: Tỷ lệ hài lòng của KH/tổng số KH được khảo sát | F24: TH ≥ 80%KH: KPI = TH/KH*100% TH < 80%KH: KPI = 0% Max KPI = 120% | G24: 46022 | H24: Báo cáo của TT CSKH | I24: % | J24: 0.8 | K24: 0.8 | L24: =IF(LEN(K24)=0,"",IF(K24<J24*80%,0,MIN(120%,K24/J24*100%))) -> 1 | M24: =IFERROR(L24*D24,"") -> 0.15
B25: 3 | C25: Thời gian xử lý đơn khiếu nại của KH (có báo cáo bằng văn bản) trung bình không quá 05 ngày làm việc kể từ ngày tiếp nhận đơn | D25: 0.15 | E25: Trung bình thời gian xử lý đơn khiếu nại của KH (có báo cáo bằng văn bản) kể từ ngày tiếp nhận đơn | F25: TH ≤ KH: KPI = KH/TH*100% TH > KH: KPI = 0% Max KPI = 120% | G25: 46022 | H25: Báo cáo của TT CSKH | I25: Ngày | J25: 5 | K25: 5 | L25: =IF(LEN(K25)=0,"",IF(K25>J25,0,MIN(120%,J25/K25*100%))) -> 1 | M25: =IFERROR(L25*D25,"") -> 0.15
B26: 4 | C26: Tỷ lệ phản ánh về chất lượng dịch vụ giảm 5% so với tổng phản ánh năm trước | D26: 0.15 | E26: Tỷ lệ giảm phản ánh về chất lượng dịch vụ so với tổng số phản ánh năm trước | F26: TH ≥ 80%KH: KPI = TH/KH*100% TH < 80%KH: KPI = 0% Max KPI = 120% | G26: 46022 | H26: Báo cáo của TT CSKH | I26: % | J26: 0.05 | K26: 0.05 | L26: =IF(LEN(K26)=0,"",IF(K26<J26*80%,0,MIN(120%,K26/J26*100%))) -> 1 | M26: =IFERROR(L26*D26,"") -> 0.15
B27: 5 | C27: Đảm bảo ≥ 2% khách hàng/tổng số khách hàng được thiết lập hồ sơ quản lý (tính scan hợp đồng để tạo mã dữ liệu KH) | D27: 0.2 | E27: Tỷ lệ khách hàng/tổng số khách hàng được thiết lập hồ sơ quản lý (chỉ tính scan hợp đồng để tạo mã HĐ và mã KH) | F27: TH ≥ KH: KPI = TH/KH*100% TH < KH: KPI = 0% Max KPI = 120% | G27: 46022 | H27: TT CNTT | I27: % | J27: 0.02 | K27: 0.021 | L27: =IF(LEN(K27)=0,"",IF(K27<J27,0,MIN(120%,K27/J27*100%))) -> 1.05 | M27: =IFERROR(L27*D27,"") -> 0.21
B28: 6 | C28: Tỷ lệ người dùng đăng ký Zalo OA của Công ty đạt ≥ 86% | D28: 0.15 | E28: Tỷ lệ người dùng đăng ký Zalo OA của Công ty | F28: TH ≥ KH, KPI = 100% TH < KH, KPI = 0 | G28: 46022 | H28: Báo cáo của TT CSKH | I28: % | J28: 0.86 | K28: 0.87 | L28: =IF(LEN(K28)=0,"",IF(K28>=J28,100%,0%)) -> 1 | M28: =IFERROR(L28*D28,"") -> 0.15
C29: PHÁT TRIỂN ĐỔI MỚI | D29: 0.15 | M29: =SUM(M30:M33)*D29 -> 0.15
B30: 1 | C30: Hoàn thành xây dựng và vận hành hệ thống BSC-KPI trước ngày 31/12/2025 | D30: 0.4 | E30: Thời gian hoàn thành xây dựng và vận hành hệ thống BSC-KPI | F30: TH ≤ KH, KPI = 100% TH > KH, KPI = 0% | G30: 46022 | H30: Báo cáo của Ban Nhân sự | I30: Ngày | J30: 46022 | K30: 46022 | L30: =IF(LEN(K30)=0,"",IF(K30<=J30,1,0)) -> 1 | M30: =IFERROR(L30*D30,"") -> 0.4
B31: 2 | C31: Đảm bảo có ít nhất 01 sáng kiến cải tiến cấp Công ty | D31: 0.2 | E31: Số lượng sáng kiến cải tiến cấp Công ty | F31: TH ≥ KH, KPI = 100% TH < KH, KPI = 0 | G31: 46022 | H31: Quyết định công nhận sáng kiến | I31: Sáng kiến | J31: 1 | K31: 1 | L31: =IF(LEN(K31)=0,"",IF(K31>=J31,100%,0%)) -> 1 | M31: =IFERROR(L31*D31,"") -> 0.2
B32: 3 | C32: Tổ chức 03 khóa đào tạo | D32: 0.2 | E32: Số khoá đào tạo được tổ chức | F32: TH ≥ KH, KPI = 100% TH < KH, KPI = 0 | G32: 46022 | H32: Báo cáo của Ban Nhân sự | I32: Khoá đào tạo | J32: 3 | K32: 3 | L32: =IF(LEN(K32)=0,"",IF(K32>=J32,100%,0%)) -> 1 | M32: =IFERROR(L32*D32,"") -> 0.2
B33: 4 | C33: Có ít nhất 01 đề tài/dự án phát triển KHCN được ứng dụng | D33: 0.2 | E33: Số lượng đề tài/dự án phát triển KHCN được ứng dụng | F33: TH ≥ KH, KPI = 100% TH < KH, KPI = 0 | G33: 46022 | H33: QĐ phê duyệt ứng dụng của HĐQT | I33: Đề tài/ Dự án | J33: 1 | K33: 1 | L33: =IF(LEN(K33)=0,"",IF(K33>=J33,100%,0%)) -> 1 | M33: =IFERROR(L33*D33,"") -> 0.2
B34: TỔNG: | D34: =D9+D15+D22+D29 -> 1 | M34: =SUM(M29,M22,M15,M9) -> 1.0403071
C36: Người lập (Prepared by) | F36: Xem xét (Checked by) | K36: Phê duyệt (Approved by)
C37: Trưởng phòng …........... | F37: Phó Giám đốc | K37: Giám đốc
C43: Ngày (Date) ....../....../...... | F43: Ngày (Date) ....../....../...... | K43: Ngày (Date) ....../....../......

Sheet Bảng đánh giá KPI (ĐK thêm)
C1: CÔNG TY CỔ PHẦN CẤP NƯỚC ĐÀ NẴNG
B2: BẢNG XÁC NHẬN KẾT QUẢ KPI BAN HÀNH CHÍNH - NHÂN SỰ - QUÝ 4/NĂM 2025 - MỤC TIÊU ĐĂNG KÝ THÊM Nếu đúng thì dấu ✔, Sai thì điền số liệu đúng vào
B4: STT | C4: Mục tiêu đánh giá | D4: Phương pháp đo | E4: Nguồn chứng minh | F4: ĐVT | G4: Kế hoạch (KH) | H4: Thực hiện (TH) | I4: Ban Kế hoạch | J4: Ban Kỹ thuật | K4: Ban Tài chính - Kế toán | L4: Trung tâm QLVH | M4: Ban HCNS | N4: Trung tâm CNTT | O4: XNCN KV I | P4: XNCN KV II | Q4: XNCN KV III | R4: XNCN KV IV
B5: 1 | C5: Hoàn thành bàn giao kiểm kê CCDC năm 2024 do Ban HCNS phụ trách trước ngày 30/11/2025 | D5: TH ≤ KH, KPI = 100% TH > KH, KPI = 0% | E5: Ban TCKT | F5: Ngày | G5: 45991
B6: 2 | C6: Đảm bảo tuân thủ 100% chế độ chính sách quy định về PCCC, ATVSLĐ | D6: TH = 0, KPI = 100% TH ≥ 1, KPI = 0% | E6: Ban HCNS | F6: Lần | G6: 0
B7: 3 | C7: Hoàn thành báo cáo kiểm tra tuân thủ nội quy lao động trước ngày 02 hàng tháng | D7: TH = 0, KPI = 100% TH ≥ 1, KPI = 0% | E7: Ban HCNS | F7: Lần | G7: 0
B8: 4 | C8: Không quá 1 lần sai sót/chậm trễ trong việc tính lương, thực hiện chế độ chính sách cho người lao động hoặc báo cáo số liệu liên quan cho Giám đốc ban/các đơn vị | D8: TH ≤ KH, KPI = 100% TH > KH, KPI = 0% | E8: Ban HCNS Tổng hợp báo cáo, Ban TCKT xác nhận | F8: Lần | G8: 1
B9: 5 | C9: Đảm bảo 100% tham mưu pháp lý cho HĐQT, Ban Điều hành | D9: TH ≥ KH, KPI = 100% TH < KH, KPI = 0 | E9: Ban HCNS báo cáo | F9: Lần | G9: 1
B10: 6 | C10: Kiểm soát tiến độ xử lý văn bản, hồ sơ đúng hạn đạt 100% | D10: TH = 0, KPI = 100% TH ≥ 1, KPI = 0% | E10: Ban HCNS | F10: Lần | G10: 0
B11: 7 | C11: Đảm bảo theo dõi, ký mới và gia hạn 100% hợp đồng lao động đúng quy định | D11: TH = 0, KPI = 100% TH ≥ 1, KPI = 0% | E11: Ban HCNS | F11: Lần | G11: 0
B12: 8 | C12: Hoàn thành báo cáo kiểm kê CCDC năm 2024 do Ban HCNS phụ trách trước ngày 31/12/2025 | D12: TH ≥ KH, KPI = 100% TH < KH, KPI = 0 | E12: Ban HCNS | F12: Ngày | G12: 46022
B13: 9 | C13: Không có phản ánh, phàn nàn của khách hàng, khách mời về công tác lễ tân khánh tiết | D13: TH = 0, KPI = 100% TH ≥ 1, KPI = 0% | E13: Ban HCNS | F13: Lần | G13: 0
B14: 10 | C14: 100% hồ sơ, công văn được lưu trữ đúng quy định (nơi nhận, thời hạn…) | D14: TH = 0, KPI = 100% TH ≥ 1, KPI = 0% | E14: Ban HCNS | F14: Lần | G14: 0
B15: 11 | C15: Đảm bảo 100% công văn đi - đến được xử lý đúng hạn (tại giai đoạn theo chức năng Ban HCNS) | D15: TH = 0, KPI = 100% TH ≥ 1, KPI = 0% | E15: Ban HCNS | F15: Lần | G15: 0
B16: 12 | C16: Đảm bảo không vi phạm Luật ATGT | D16: TH = 0, KPI = 100% TH ≥ 1, KPI = 0% | E16: Ban HCNS | F16: Lần | G16: 0
... B22: 18 | C22: Không có trường hợp KH phàn nàn vì cuộc gọi nhỡ do yếu tố chủ quan | D22: TH = 0, KPI = 100% TH ≥ 1, KPI = 0% | E22: Ban HCNS | F22: Lần | G22: 0
B23: CHỮ KÝ XÁC NHẬN

Sheet A7.10.NH KPI CÁ NHÂN
B2: Dự án: | C2: XÂY DỰNG HỆ THỐNG ĐÁNH GIÁ HIỆU QUẢ CÔNG VIỆC
B3: Yêu cầu: | C3: CÔNG TY CỔ PHẦN CẤP NƯỚC ĐÀ NẴNG
B4: Tư vấn: | C4: BrainMark Vietnam
B6: A7.10 | C6: NGÂN HÀNG KPI CÁ NHÂN
C7: PHÒNG PTTT
C8: VỊ TRÍ: CHUYÊN VIÊN NHÂN SỰ
B10: STT | C10: NGÂN HÀNG MỤC TIÊU | D10: ĐVT | E10: PHƯƠNG PHÁP ĐO
B11: 1
B12: 2
B13: 3
B14: 4
B15: 5
B16: 6
B17: 7
B18: 8
B19: 9
B20: 10
C22: HƯỚNG DẪN CHUNG
C23: Từ viết tắt
C24: KH: Kế hoạch
C25: TH: Thực hiện
C26: Cách đặt mục tiêu
C27: - Danh từ + động từ + chỉ tiêu
C28: - Chỉ tiêu ghi vào cột kế hoạch (KH)
C29: Các thang đo thưởng gặp trong KPI
C30: Tham khảo tài liệu hướng dẫn các thang đo trong KPI

Sheet A7.9.KPI Ban HCNS năm 2026
B2: Dự án: | C2: XÂY DỰNG HỆ THỐNG ĐÁNH GIÁ HIỆU QUẢ CÔNG VIỆC
B3: Yêu cầu: | C3: CÔNG TY CỔ PHẦN CẤP NƯỚC ĐÀ NẴNG
B4: Tư vấn: | C4: BrainMark Vietnam
B6: A7.9 | C6: KPI BAN HCNS - NĂM 2026
B9: STT | C9: Mục tiêu | D9: Trọng số (%) | E9: Tiêu chí đánh giá | F9: Phương pháp đo | G9: Thời điểm ghi nhận | H9: Nguồn chứng minh | I9: ĐVT | J9: Kế hoạch (KH) | K9: Thực hiện (TH) | L9: Hoàn thành | M9: Kết quả KPI
C10: VẬN HÀNH (B) | D10: 0.4
B11: 1 | C11: Hoàn thành 95% các công việc theo phiếu giao việc, thông báo họp giao ban và thông báo khác của Ban Tổng giám đốc giao | D11: 0.2 | E11: Tỷ lệ hoàn thành các công việc theo Ban TGĐ giao (trong cuộc họp giao ban) thực tế | F11: TH ≥ KH, KPI = 100% TH < KH, KPI = 0 | G11: 46387 | H11: Ban Kế hoạch chủ trì, phối hợp với Ban TCKT, Ban HCNS, Ban Kỹ thuật,… | I11: % | J11: 0.95 | L11: =IF(LEN(K11)=0,"",IF(K11>=J11,100%,0%)) | M11: =IFERROR(L11*D11,"")
B12: 2 | C12: Tỷ lệ văn bản, hồ sơ xử lý đúng hạn sau khi tiếp nhận văn bản ≥ 90%/tổng số lượng văn bản văn phòng điện tử tiếp nhận | D12: 0.2 | E12: Tỷ lệ văn bản, hồ sơ xử lý đúng hạn sau khi tiếp nhận văn bản/tổng số lượng văn bản văn phòng điện tử tiếp nhận thực tế | F12: TH < 80%: KPI= 0 TH ≥ 80%: TH/KH*100% Max KPI = 120% | G12: 46387 | H12: Ban HCNS báo cáo, Ban kế hoạch xác nhận | I12: % | J12: 0.9 | L12: =IF(LEN(K12)=0,"",IF(K12<80%,0,MIN(120%,K12/J12*100%))) | M12: =IFERROR(L12*D12,"") | N12: =IF(LEN(M12)=0,"",IF(AND(M12>=L12,M12<100%),100%,IF(M12=100%,120%,0%)))
B13: 3 | C13: Đảm bảo 100% công văn đi đến được xử lý đúng hạn (tại giai đoạn theo chức năng Ban HCNS) | D13: 0.2 | E13: Số lần công văn đi đến xử lý trễ hạn (tại giai đoạn theo chức năng Ban HCNS) thực tế | F13: TH = 0, KPI = 100% TH ≥ 1, KPI = 0% | G13: 46387 | H13: Báo cáo của Ban HCNS | I13: Lần | J13: 0 | L13: =IF(LEN(K13)=0,"",IF(K13=J13,1,0)) | M13: =IFERROR(L13*D13,"")
B14: 4 | C14: Đảm bảo tuân thủ 100% chế độ chính sách quy định Luật Lao động (HĐLĐ, Chế độ nghỉ hưu, nghỉ trước tuổi, nâng lương,…) | D14: 0.15 | E14: Số lần vi phạm thực hiện chế độ chính sách quy định Luật Lao động (HĐLĐ, Chế độ nghỉ hưu, nghỉ trước tuổi, nâng lương,…) | F14: TH = 0, KPI = 100% TH ≥ 1, KPI = 0% | G14: 46387 | H14: Báo cáo của Ban HCNS, Ban TCKT xác nhận | I14: Lần | J14: 0 | L14: =IF(LEN(K14)=0,"",IF(K14=J14,1,0)) | M14: =IFERROR(L14*D14,"")
B15: 5 | C15: Đảm bảo trình HĐQT phê duyệt kế hoạch lao động tiền lương và quyết toán tiền lương năm trước trước 31/3/2026 | D15: 0.25 | E15: Thời gian thực tế trình phê duyệt kế hoạch lao động tiền lương và quyết toán tiền lương năm trước | F15: TH ≤ KH, KPI = 100% TH > KH, KPI = 0% | G15: 46112 | H15: Báo cáo của Ban HCNS, Ban TCKT xác nhận | I15: Ngày | J15: 46112 | L15: =IF(LEN(K15)=0,"",IF(K15<=J15,1,0)) | M15: =IFERROR(L15*D15,"")
C16: TÀI CHÍNH (F) | D16: 0.25
B17: 1 | C17: Chi phí Văn phòng phẩm (bộ phận văn phòng công ty) giảm 2% so với năm trước | D17: 0.4 | E17: Tỷ lệ chi phí VVP (bộ phận VP Công ty) giảm so với năm 2025 thực tế | F17: TH ≥ KH: KPI = TH/KH*100% TH < KH: KPI = 0% Max KPI = 120% | G17: 46387 | H17: Ban TCKT xác nhận | I17: % | J17: 0.02 | L17: =IF(LEN(K17)=0,"",MAX(0%,IF(K17<J17,0,(MIN(120%,K17/J17*100%))))) | M17: =IFERROR(L17*D17,"")
B18: 2 | C18: Kinh phí Đào tạo không vượt quá kế hoạch được duyệt trong năm | D18: 0.4 | E18: Tỷ lệ kinh phí đào tạo so với kế hoạch đào tạo được duyệt trong năm thực tế | F18: TH <= KH: KPI = 100% TH > KH: KPI =0% | G18: 46387 | H18: Báo cáo của Ban HCNS, Ban TCKT xác nhận | I18: % | J18: 1 | L18: =IF(LEN(K18)=0,"",IF(K18<=J18,1,0)) | M18: =IFERROR(L18*D18,"")
B19: 3 | C19: Sản lượng điện tiêu thụ thụ văn phòng cty năm 2026 không tăng so với năm 2025 | D19: 0.2 | E19: Sản lượng điện tiêu thụ 2026 (VPCT) thực tế so với năm 2025 | F19: TH ≥ KH: KPI = TH/KH*100% TH < KH: KPI = TH/KH*100% Max KPI = 120% | G19: 46387 | H19: Báo cáo của Ban HCNS, Ban TCKT xác nhận | I19: kWh | J19: Số liệu 2025 | L19: =IF(LEN(K19)=0,"",IF(K19>J19,0,MIN(120%,J19/K19*100%))) | M19: =IFERROR(L19*D19,"")
C20: KHÁCH HÀNG (C) | D20: 0.15
B21: 1 | C21: Không quá 4 lần/người/năm phàn nàn của khách hàng về thái độ tiếp xúc, chăm sóc khách hàng của Bộ phận Call Center | D21: 0.25 | E21: Số lần phàn nàn của khách hàng về thái độ tiếp xúc, chăm sóc khách hàng của Bộ phận Call Center | F21: TH ≤ KH: KPI = 100% TH > KH: KPI = 0% | G21: 46387 | H21: Ban HCNS xác nhận | I21: Lần | J21: 4 | L21: =IF(LEN(K21)=0,"",IF(K21<=J21,1,0)) | M21: =IFERROR(L21*D21,"")
B22: 2 | C22: Đảm bảo hoàn thành khảo sát mức độ hài lòng của khách hàng (theo chủ trương của HĐQT) | D22: 0.15 | E22: Số lần chậm trễ hoàn thành khoả sát mức độ hài lòng của khách hàng (theo chủ trương của HĐQT) thực tế | F22: TH = 0, KPI = 100% TH ≥ 1, KPI = 0% | G22: 46387 | H22: TTCNTT xác nhận | I22: Ngày | J22: 46387 | L22: =IF(LEN(K22)=0,"",IF(K22=J22,1,0)) | M22: =IFERROR(L22*D22,"")
B23: 3 | C23: Thời gian xử lý đơn khiếu nại của KH (có báo cáo bằng văn bản) trung bình không quá 05 ngày làm việc kể từ ngày tiếp nhận đơn | D23: 0.2 | E23: Trung bình thời gian xử lý đơn khiếu nại của KH (có báo cáo bằng văn bản) kể từ ngày tiếp nhận đơn | F23: TH ≤ KH: KPI = KH/TH*100% TH > KH: KPI = 0% Max KPI = 120% | G23: 46387 | H23: HCNS báo cáo, các XN liên quan xác nhận | I23: Ngày | J23: 5 | L23: =IF(LEN(K23)=0,"",IF(K23>J23,0,MIN(120%,J23/K23*100%))) | M23: =IFERROR(L23*D23,"")
B24: 4 | C24: Tỷ lệ phản ánh về chất lượng dịch vụ giảm 5% so với tổng phản ánh năm trước | D24: 0.15 | E24: Tỷ lệ giảm phản ánh về chất lượng dịch vụ so với tổng số phản ánh năm trước | F24: TH ≥ 80%KH: KPI = TH/KH*100% TH < 80%KH: KPI = 0% Max KPI = 120% | G24: 46387 | H24: HCNS báo cáo, các XN liên quan xác nhận | I24: % | J24: 5 | L24: =IF(LEN(K24)=0,"",IF(K24=J24,1,0)) | M24: =IFERROR(L24*D24,"")
B25: 5 | C25: Đảm bảo 80% hồ sơ (hồ sơ nhân sự) được số hoá trước 31/12/2026 | D25: 0.25 | E25: Tỷ lệ hồ sơ (hồ sơ nhân sự) được số hoá thực tế | F25: TH < KH: KPI = 0% TH ≥ KH: KPI = TH/KH*100% | G25: 46387 | H25: TT CNTT xác nhận | I25: % | J25: 0.8 | L25: =IF(LEN(K25)=0,"",IF(K25<J25,0,MIN(120%,K25/J25*100%))) | M25: =IFERROR(L25*D25,"")
C26: PHÁT TRIỂN (L) | D26: 0.2
B27: 1 | C27: Hoàn thành xây dựng hệ thống lương 3P trước ngày 31/12/2026 | D27: 0.4 | E27: Thời gian hoàn thành xây dựng và vận hành hệ thống lương 3P | F27: TH ≤ KH, KPI = 100% TH > KH, KPI = 0% | G27: 46387 | H27: Ban KPI | I27: Ngày | J27: 46387 | L27: =IF(LEN(K27)=0,"",IF(K27<=J27,1,0)) | M27: =IFERROR(L27*D27,"")
B28: 2 | C28: Hoàn thành việc xây dựng lại đơn giá tiền lương và hệ số lương của Biên đọc (nhằm nâng cao NSLĐ) HĐ lương phê duyệt trước 31/12/2026 | D28: 0.15 | E28: Thời gian hoàn thành việc xây dựng lại đơn giá tiền lương và hệ số lương của Biên đọc (nhằm nâng cao NSLĐ) trình HĐ lương thực tế | F28: TH ≤ KH, KPI = 100% TH > KH, KPI = 0% | G28: 46387 | H28: Hội đồng lương | I28: Ngày | J28: 46387 | L28: =IF(LEN(K28)=0,"",IF(K28<=J28,1,0)) | M28: =IFERROR(L28*D28,"")
B29: 3 | C29: Tổ chức 03 khóa đào tạo | D29: 0.2 | E29: Số khoá đào tạo được tổ chức | F29: TH ≥ KH, KPI = 100% TH < KH, KPI = 0 | G29: 46387 | H29: HCNS báo cáo, Ban Kế hoạch xác nhận | I29: Khoá đào tạo | J29: 3 | L29: =IF(LEN(K29)=0,"",IF(K29>=J29,100%,0%)) | M29: =IFERROR(L29*D29,"")
B30: 4 | C30: Ứng dụng AI trong việc lập Kết luận giao ban hàng tháng | D30: 0.25 | E30: Số lần ứng dụng AI trong việc lập Kết luận giao ban hàng tháng | F30: TH ≥ KH, KPI = 100% TH < KH, KPI = 0 | G30: 46387 | H30: TT CNTT xác nhận | I30: Lần | J30: 1 | L30: =IF(LEN(K30)=0,"",IF(K30>=J30,100%,0%)) | M30: =IFERROR(L30*D30,"")
B31: TỔNG: | D31: 1
C33: Người lập | F33: Giám đốc Ban HCNS | J33: Phê duyệt
C40: Ngày (Date) ....../....../...... | F40: Ngày (Date) ....../....../...... | K40: Ngày (Date) ....../....../......

Sheet 1.KPI nam.PGĐ(HC-TS-ATNB)
B2: Dự án: | C2: XÂY DỰNG HỆ THỐNG ĐÁNH GIÁ HIỆU QUẢ CÔNG VIỆC
B3: Yêu cầu: | C3: CÔNG TY CỔ PHẦN CẤP NƯỚC ĐÀ NẴNG
B4: Tư vấn: | C4: BrainMark Vietnam
B6: A7.11 | C6: KPI NHÂN VIÊN - NĂM 2026
B8: Họ và tên: | C8: Nguyễn Văn Vinh | E8: Chức danh: | F8: Phó Giám đốc Ban (Hành chính - Nội quy, Hành chính - Tài sản, An ninh - ATNB)
B9: Mã nhân viên: | C9: 0267 | E9: Đơn vị: | F9: Ban HCNS
B11: I | C11: KPI CÔNG TY VÀ KPI NĂM ĐƠN VỊ | Q11: =Q13+Q14 -> 0
C12: Nội dung | I12: Trọng số (%) | L12: Kế hoạch (KH) | N12: Thực hiện (TH) | O12: Hoàn thành | P12: Ghi chú | Q12: Kết quả KPI
B13: 1 | C13: Kết quả KPI Công ty | I13: 0.4 | L13: 1 | O13: =N13/L13 -> 0 | Q13: =I13*O13 -> 0
B14: 2 | C14: Kết quả KPI Đơn vị | I14: 0.6 | L14: 1 | O14: =N14/L14 -> 0 | Q14: =I14*O14 -> 0
B15: II | C15: MỤC TIÊU QUAN TRỌNG TRONG NĂM | Q15: =SUM(Q17:Q21) -> 0
C16: Mục tiêu | D16: Trọng số (%) | E16: Tiêu chí đánh giá | G16: Phương pháp đo | I16: Nguồn chứng minh | L16: ĐVT | N16: Kế hoạch (KH) | O16: Thực hiện (TH) | P16: Hoàn thành | Q16: Kết quả KPI
B17: 1 | C17: Tỷ lệ văn bản, hồ sơ xử lý đúng hạn sau khi tiếp nhận văn bản ≥ 90%/tổng số lượng văn bản văn phòng điện tử tiếp nhận | D17: 0.15 | E17: Tỷ lệ văn bản, hồ sơ xử lý đúng hạn sau khi tiếp nhận văn bản/tổng số lượng văn bản văn phòng điện tử tiếp nhận thực tế | G17: TH < 80%: KPI= 0 TH ≥ 80%: TH/KH*100% Max KPI = 120% | I17: Ban HCNS báo cáo, Ban kế hoạch xác nhận | L17: % | N17: 0.9 | P17: =IF(LEN(O17)=0,"",IF(O17<80%,0,MIN(120%,O17/N17*100%))) | Q17: =IFERROR(P17*D17,"")
B18: 3 | C18: Đảm bảo tuân thủ 100% quy định về PCCC, ATVSLĐ | D18: 0.2 | E18: Số lần vi phạm chế độ chính sách quy định về PCCC, ATVSLĐ thực tế | G18: TH = 0, KPI = 100% TH ≥ 1, KPI = 0% | I18: Ban HCNS | L18: Lần | N18: 0 | P18: =IF(LEN(O18)=0,"",IF(O18=N18,1,0)) | Q18: =IFERROR(P18*D18,"")
